Workbook

Sheet Situation actuelle
A1: BUDGET GARDE D'ENFANTS - FAMILLE DIEUDONNÉ
A3: PARAMÈTRES DU FOYER
A4: Ville | B4: Nantes
A5: Revenus annuels du foyer (N-2) | B5: 90000
A6: Revenus mensuels | B6: =B5/12 -> 7500
A7: Nombre d'enfants | B7: 2
A8: Enfant 1 - âge | B8: 4,5 ans (école maternelle)
A9: Enfant 2 - âge | B9: 2 ans (crèche municipale)
A10: Situation du couple | B10: 1 salarié + 1 chômage
A13: BARÈMES 2026 (sources: CAF, CNAF, URSSAF)
A14: Taux d'effort crèche (2 enfants) | B14: 0.000516
A15: Taux d'effort CMG ass. mat. (2 enfants) | B15: 0.000516
A16: Taux d'effort CMG garde domicile (×2) | B16: =B15*2 -> 0.001032
A17: Coût horaire de référence CMG | B17: 10.5
A18: Plafond horaire CMG garde domicile | B18: 15.18
A19: Plafond crédit impôt garde hors domicile / enfant | B19: 3500
A20: Plafond crédit impôt emploi domicile | B20: 12000
A21: Majoration CI emploi domicile / enfant | B21: 1500
A22: Taux crédit d'impôt | B22: 0.5
A25: 1. CRÈCHE MUNICIPALE (enfant de 2 ans)
A26: Jours par semaine | B26: 4
A27: Heures par jour | B27: 9
A28: Semaines par an (hors vacances) | B28: 47
A29: Heures par mois | B29: =B26*B27*52/12 -> 156
A30: Heures par an | B30: =B26*B27*B28 -> 1692
A31: Tarif horaire crèche | B31: =B6*B14 -> 3.87
A32: Coût mensuel crèche | B32: =B31*B29 -> 603.72
A33: Coût annuel crèche brut | B33: =B31*B30 -> 6548.04
A34: Crédit d'impôt (50% plafonné à 3 500€/enfant) | B34: =MIN(B33*B22, B19*B22) -> 1750
A35: COÛT ANNUEL CRÈCHE NET (après CI) | B35: =B33-B34 -> 4798.04
A37: 2. NOUNOU À DOMICILE (2 enfants, soirs + mercredis)
A38: Salaire net horaire | B38: 9.73
A39: Salaire brut horaire estimé (net / 0.78) | B39: =B38/0.78 -> 12.474359
A40: Taux charges patronales (après abattement ~35%) | B40: 0.35
A41: Charges patronales horaires | B41: =B39*B40 -> 4.3660256
A42: Coût total employeur par heure | B42: =B39+B41 -> 16.840385
A44: Heures par semaine (soirs + mercredi) | B44: 17.5
A45: Semaines par an | B45: 47
A46: Heures par mois | B46: =B44*52/12 -> 75.833333
A47: Heures par an | B47: =B44*B45 -> 822.5
...

Sheet Scénario optimal
A1: COMPARATIF FINAL — MENSUALISATION 52 SEMAINES (CP inclus)
A2: Objectif : ~1 000€/mois pour Mona — 2 options au plus près du plafond CI
B4: ACTUEL | C4: OPTION A 10,50€/h (sous plafond) | D4: OPTION B 11,00€/h (léger dépassement) | E4: ÉCART (B vs actuel)
A6: PARAMÈTRES DU CONTRAT (déclaré)
A7: Mensualisation (semaines) | B7: 52 | C7: 52 | D7: 52
A8: Taux horaire net | B8: 9.73 | C8: 10.5 | D8: 11
A9: Heures / semaine | B9: 17 | C9: 20 | D9: 20
A10: Heures mensualisées (h/sem × 52 / 12) | B10: =B9*B7/12 -> 73.666667 | C10: =C9*C7/12 -> 86.666667 | D10: =D9*D7/12 -> 86.666667 | E10: =D10-B10 -> 13
A12: CE QUE GAGNE MONA
A13: Salaire net mensualisé (déclaré) | B13: =B8*B10 -> 716.77667 | C13: =C8*C10 -> 910 | D13: =D8*D10 -> 953.33333 | E13: =D13-B13 -> 236.55667
A15: COÛT EMPLOYEUR (déclaré)
A16: Coût total employeur / heure (brut+charges) | B16: =B8/0.78*1.35 -> 16.840385 | C16: =C8/0.78*1.35 -> 18.173077 | D16: =D8/0.78*1.35 -> 19.038462
A17: Coût employeur mensuel | B17: =B16*B10 -> 1240.575 | C17: =C16*C10 -> 1575 | D17: =D16*D10 -> 1650
A18: Coût employeur annuel | B18: =B17*12 -> 14886.9 | C18: =C17*12 -> 18900 | D18: =D17*12 -> 19800 | E18: =D18-B18 -> 4913.1
A20: AIDES
A21: Revenus mensuels foyer | B21: 7500 | C21: 7500 | D21: 7500
A22: Taux d'effort CMG domicile (2 enfants) | B22: 0.001032 | C22: 0.001032 | D22: 0.001032
A23: Coût de référence CMG | B23: 10.5 | C23: 10.5 | D23: 10.5
A24: Plafond horaire CMG domicile | B24: 15.18 | C24: 15.18 | D24: 15.18
A26: CMG mensuel | B26: =MIN(B16,B24)*B10*(1-(B21*B22/B23)) -> 293.94263 | C26: =MIN(C16,C24)*C10*(1-(C21*C22/C23)) -> 345.81486 | D26: =MIN(D16,D24)*D10*(1-(D21*D22/D23)) -> 345.81486 | E26: =D26-B26 -> 51.872229
A27: CMG annuel | B27: =B26*12 -> 3527.3115 | C27: =C26*12 -> 4149.7783 | D27: =D26*12 -> 4149.7783
A29: Reste à charge annuel (avant CI) | B29: =B18-B27 -> 11359.588 | C29: =C18-C27 -> 14750.222 | D29: =D18-D27 -> 15650.222
A30: Plafond CI emploi domicile | B30: 15000 | C30: 15000 | D30: 15000
A31: Dépassement du plafond CI | B31: =IF(B29>B30,"Oui: "&TEXT(B29-B30,"# ##0€")&" → perte CI "&TEXT((B29-B30)*0.5,"# ##0€"),"Non (marge "&TEXT(B30-B29,"# ##0€")&")") -> Non (marge 3 640€) | C31: =IF(C29>C30,"Oui: "&TEXT(C29-C30,"# ##0€")&" → perte CI "&TEXT((C29-C30)*0.5,"# ##0€"),"Non (marge "&TEXT(C30-C29,"# ##0€")&")") -> Non (marge 250€) | D31: =IF(D29>D30,"Oui: "&TEXT(D29-D30,"# ##0€")&" → perte CI "&TEXT((D29-D30)*0.5,"# ##0€"),"Non (marge "&TEXT(D30-D29,"# ##0€")&")") -> Oui: 650€ → perte CI 325€
A32: Crédit d'impôt annuel (50% plafonné) | B32: =MIN(B29,B30)*0.5 -> 5679.7942 | C32: =MIN(C29,C30)*0.5 -> 7375.1109 | D32: =MIN(D29,D30)*0.5 -> 7500 | E32: =D32-B32 -> 1820.2058
A34: COÛT NET DÉCLARÉ
A35: Coût net annuel nounou (après CMG + CI) | B35: =B29-B32 -> 5679.7942 | C35: =C29-C32 -> 7375.1109 | D35: =D29-D32 -> 8150.2217
A36: Coût net mensuel nounou (déclaré) | B36: =B35/12 -> 473.31619 | C36: =C35/12 -> 614.59257 | D36: =D35/12 -> 679.18514 | E36: =D36-B36 -> 205.86896
A38: COMPLÉMENT CASH (babysitting vacances)
A39: Semaines de babysitting cash | B39: 0 | C39: 3 | D39: 2
A40: Tarif par semaine | B40: 0 | C40: 300 | D40: 250
A41: Cash annuel | B41: =B39*B40 -> 0 | C41: =C39*C40 -> 900 | D41: =D39*D40 -> 500
A42: Cash mensuel (lissé) | B42: =B41/12 -> 0 | C42: =C41/12 -> 75 | D42: =D41/12 -> 41.666667
A44: BILAN FINAL
A45: Rémunération totale Mona / mois | B45: =B13+B42 -> 716.77667 | C45: =C13+C42 -> 985 | D45: =D13+D42 -> 995 | E45: =D45-B45 -> 278.22333
A46: Rémunération totale Mona / an | B46: =B45*12 -> 8601.32 | C46: =C45*12 -> 11820 | D46: =D45*12 -> 11940
A48: Coût réel famille / mois (déclaré + cash) | B48: =B36+B42 -> 473.31619 | C48: =C36+C42 -> 689.59257 | D48: =D36+D42 -> 720.85181 | E48: =D48-B48 -> 247.53562
A49: Coût réel famille / an | B49: =B48*12 -> 5679.7942 | C49: =C48*12 -> 8275.1109 | D49: =D48*12 -> 8650.2217
A51: + Crèche net annuel (inchangé) | B51: ='Situation actuelle'!B35 -> 4798.04 | C51: ='Situation actuelle'!B35 -> 4798.04 | D51: ='Situation actuelle'!B35 -> 4798.04
A53: BUDGET GARDE TOTAL / mois | B53: =(B49+B51)/12 -> 873.15285 | C53: =(C49+C51)/12 -> 1089.4292 | D53: =(D49+D51)/12 -> 1120.6885 | E53: =D53-B53 -> 247.53562
...

Sheet Objectif 1000€ nounou
A1: OBJECTIF: 1 000€ NET/MOIS POUR LA NOUNOU
A2: Comparatif des scénarios — coût réel pour la famille après CMG + crédit d'impôt
B4: Actuel (référence) | C4: A: +heures 10,50€/h, 22h/sem | D4: B: +taux 11€/h, 21h/sem | E4: C: +heures +vacances 10,50€/h, 22h+2sem | F4: D: +vacances 11,50€/h, 20h/sem
A5: CE QUE GAGNE LA NOUNOU
A6: Taux net horaire | B6: 9.73 | C6: 10.5 | D6: 11 | E6: 10.5 | F6: 11.5
A7: Heures/semaine (moyenne annualisée) | B7: 17.1 | C7: 22 | D7: 21 | E7: 22.9 | F7: 20
A8: Heures/mois (mensualisé) | B8: =B7*52/12 -> 74.1 | C8: =C7*52/12 -> 95.333333 | D8: =D7*52/12 -> 91 | E8: =E7*52/12 -> 99.233333 | F8: =F7*52/12 -> 86.666667
A9: Salaire net mensuel nounou | B9: =B6*B8 -> 720.993 | C9: =C6*C8 -> 1001 | D9: =D6*D8 -> 1001 | E9: =E6*E8 -> 1041.95 | F9: =F6*F8 -> 996.66667
A11: CE QUE VOUS PAYEZ (employeur)
A12: Coût total employeur/heure | B12: =B6/0.78*1.35 -> 16.840385 | C12: =C6/0.78*1.35 -> 18.173077 | D12: =D6/0.78*1.35 -> 19.038462 | E12: =E6/0.78*1.35 -> 18.173077 | F12: =F6/0.78*1.35 -> 19.903846
A13: Coût employeur annuel | B13: =B12*B8*12 -> 14974.47 | C13: =C12*C8*12 -> 20790 | D13: =D12*D8*12 -> 20790 | E13: =E12*E8*12 -> 21640.5 | F13: =F12*F8*12 -> 20700
A15: VOS AIDES
A16: CMG annuel | B16: =MIN(B12,15.18)*B8*(1-(7500*0.001032/10.5))*12 -> 3548.0604 | C16: =MIN(C12,15.18)*C8*(1-(7500*0.001032/10.5))*12 -> 4564.7561 | D16: =MIN(D12,15.18)*D8*(1-(7500*0.001032/10.5))*12 -> 4357.2672 | E16: =MIN(E12,15.18)*E8*(1-(7500*0.001032/10.5))*12 -> 4751.4961 | F16: =MIN(F12,15.18)*F8*(1-(7500*0.001032/10.5))*12 -> 4149.7783
A17: Reste à charge avant CI | B17: =B13-B16 -> 11426.41 | C17: =C13-C16 -> 16225.244 | D17: =D13-D16 -> 16432.733 | E17: =E13-E16 -> 16889.004 | F17: =F13-F16 -> 16550.222
A18: Plafond CI emploi domicile | B18: 15000 | C18: 15000 | D18: 15000 | E18: 15000 | F18: 15000
A19: Crédit d'impôt (50%, plafonné) | B19: =MIN(B17,B18)*0.5 -> 5713.2048 | C19: =MIN(C17,C18)*0.5 -> 7500 | D19: =MIN(D17,D18)*0.5 -> 7500 | E19: =MIN(E17,E18)*0.5 -> 7500 | F19: =MIN(F17,F18)*0.5 -> 7500
A20: ⚠️ Plafond CI dépassé ? | B20: =IF(B17>B18,"OUI → perte "&TEXT((B17-B18)*0.5,"# ##0 €"),"Non") -> Non | C20: =IF(C17>C18,"OUI → perte "&TEXT((C17-C18)*0.5,"# ##0 €"),"Non") -> OUI → perte 613 € | D20: =IF(D17>D18,"OUI → perte "&TEXT((D17-D18)*0.5,"# ##0 €"),"Non") -> OUI → perte 716 € | E20: =IF(E17>E18,"OUI → perte "&TEXT((E17-E18)*0.5,"# ##0 €"),"Non") -> OUI → perte 945 € | F20: =IF(F17>F18,"OUI → perte "&TEXT((F17-F18)*0.5,"# ##0 €"),"Non") -> OUI → perte 775 €
A22: RÉSULTAT POUR VOTRE FAMILLE
A23: Coût net annuel NOUNOU | B23: =B17-B19 -> 5713.2048 | C23: =C17-C19 -> 8725.2439 | D23: =D17-D19 -> 8932.7328 | E23: =E17-E19 -> 9389.0039 | F23: =F17-F19 -> 9050.2217
A24: Coût net mensuel NOUNOU | B24: =B23/12 -> 476.1004 | C24: =C23/12 -> 727.10366 | D24: =D23/12 -> 744.3944 | E24: =E23/12 -> 782.41699 | F24: =F23/12 -> 754.18514
A25: + Crèche net annuel (inchangé) | B25: ='Situation actuelle'!B35 -> 4798.04 | C25: ='Situation actuelle'!B35 -> 4798.04 | D25: ='Situation actuelle'!B35 -> 4798.04 | E25: ='Situation actuelle'!B35 -> 4798.04 | F25: ='Situation actuelle'!B35 -> 4798.04
A26: TOTAL ANNUEL NET (nounou + crèche) | B26: =B23+B25 -> 10511.245 | C26: =C23+C25 -> 13523.284 | D26: =D23+D25 -> 13730.773 | E26: =E23+E25 -> 14187.044 | F26: =F23+F25 -> 13848.262
A27: TOTAL MENSUEL NET | B27: =B26/12 -> 875.93707 | C27: =C26/12 -> 1126.9403 | D27: =D26/12 -> 1144.2311 | E27: =E26/12 -> 1182.2537 | F27: =F26/12 -> 1154.0218
A29: Surcoût vs actuel (annuel) | B29: - | C29: =C26-B26 -> 3012.0391 | D29: =D26-B26 -> 3219.528 | E29: =E26-B26 -> 3675.7991 | F29: =F26-B26 -> 3337.0169
A30: Surcoût vs actuel (mensuel) | B30: - | C30: =C29/12 -> 251.00326 | D30: =D29/12 -> 268.294 | E30: =E29/12 -> 306.31659 | F30: =F29/12 -> 278.08474
A33: DÉTAIL DES SCÉNARIOS
A34: A: Augmentation + soirs allongés
A35: Passer à 10,50€/h net. Allonger les soirs de 2,5h à 3h (×4). Mercredi inchangé (10h). Total 22h/sem.
A36: B: Augmentation + mercredi allongé
A37: Passer à 11€/h net. Soirs inchangés (2,5h×4). Allonger le mercredi à 11h. Total 21h/sem.
A38: C: Augmentation + heures + vacances
A39: Passer à 10,50€/h. Soirs 3h + mer 10h + 2 semaines de garde complète (45h) pendant les vacances scolaires.
A40: D: Augmentation + congés supplémentaires
A41: Passer à 11,50€/h. Heures quasi inchangées (20h/sem). 6 semaines de congés payés (au lieu de 5).
A43: 💡 RECOMMANDATION
A44: Le scénario A est le plus avantageux pour vous : augmentation modérée (10,50€) + quelques heures en plus.
A45: C'est celui qui maximise le CMG (heures × coût plafonné). Le surcoût réel est le plus faible pour atteindre 1 000€.
A46: ⚠️ ATTENTION: Tous les scénarios dépassent le plafond du crédit d'impôt (15 000€). Chaque euro au-delà n'est remboursé qu'à ~26% (CMG seul).

Sheet Pistes & conseils
A1: PISTES D'OPTIMISATION BUDGÉTAIRE
A3: LEVIERS PRINCIPAUX IDENTIFIÉS
A5: 1. GARDE PARTAGÉE (économie potentielle: 30-40% sur la nounou)
A6: → Trouvez une famille voisine à Nantes avec des enfants d'âges proches.
A7: → Vous divisez le salaire et les charges par 2, tout en conservant le CMG et le crédit d'impôt chacun.
A8: → Sites: yoopies.fr, nounou-top.fr, bébénou.com
A10: 2. ASSISTANTE MATERNELLE LE MERCREDI (économie potentielle: 15-25%)
A11: → Une assmat agréée coûte ~4-5€/h net à Nantes (vs ~16€/h coût total nounou à domicile).
A12: → Le CMG assmat est plus avantageux (taux d'effort simple vs doublé).
A13: → Garde la nounou uniquement pour les soirs (moins d'heures = moins de coût).
A15: 3. OPTIMISER LE CRÉDIT D'IMPÔT EMPLOI À DOMICILE
A16: → Vérifiez que TOUTES les dépenses sont bien déclarées (salaire + charges - CMG).
... A39: → Les montants de ce tableur sont des estimations. Les montants réels dépendent de votre déclaration CAF.
